import React from 'react';
import { describe, it, expect, vi, beforeEach, afterEach } from 'vitest';
import { render, screen, fireEvent } from '@testing-library/react';
import '@testing-library/jest-dom';
import { ErrorBoundary, withErrorBoundary } from '../';

// Mock console.error to avoid noise in tests
const originalConsoleError = console.error;
beforeEach(() => {
  console.error = vi.fn();
});

afterEach(() => {
  console.error = originalConsoleError;
});

// Component that throws an error
const ThrowError = ({ shouldThrow = false }: { shouldThrow?: boolean }) => {
  if (shouldThrow) {
    throw new Error('Test error');
  }
  return <div>No error</div>;
};

describe('ErrorBoundary', () => {
  it('renders children when there is no error', () => {
    render(
      <ErrorBoundary>
        <div>Test content</div>
      </ErrorBoundary>
    );

    expect(screen.getByText('Test content')).toBeInTheDocument();
  });

  it('renders error fallback when child component throws', () => {
    render(
      <ErrorBoundary>
        <ThrowError shouldThrow={true} />
      </ErrorBoundary>
    );

    expect(screen.getByText('Something went wrong')).toBeInTheDocument();
    expect(screen.getByText(/We encountered an unexpected error/)).toBeInTheDocument();
  });

  it('shows error details in development mode', () => {
    // Mock development environment by mocking import.meta.env
    vi.stubEnv('DEV', true);

    render(
      <ErrorBoundary>
        <ThrowError shouldThrow={true} />
      </ErrorBoundary>
    );

    expect(screen.getByText('Error Details (Development)')).toBeInTheDocument();

    vi.unstubAllEnvs();
  });

  it('calls onError callback when error occurs', () => {
    const onError = vi.fn();

    render(
      <ErrorBoundary onError={onError}>
        <ThrowError shouldThrow={true} />
      </ErrorBoundary>
    );

    expect(onError).toHaveBeenCalledWith(
      expect.any(Error),
      expect.objectContaining({
        componentStack: expect.any(String),
      })
    );
  });

  it('resets error state when Try Again is clicked', () => {
    let shouldThrow = true;
    const TestComponent = () => {
      if (shouldThrow) {
        throw new Error('Test error');
      }
      return <div>No error</div>;
    };

    const { rerender } = render(
      <ErrorBoundary>
        <TestComponent />
      </ErrorBoundary>
    );

    expect(screen.getByText('Something went wrong')).toBeInTheDocument();

    // Reset the error state and stop throwing
    shouldThrow = false;
    fireEvent.click(screen.getByText('Try Again'));

    // Re-render with no error
    rerender(
      <ErrorBoundary>
        <TestComponent />
      </ErrorBoundary>
    );

    expect(screen.getByText('No error')).toBeInTheDocument();
  });

  it('navigates to home when Go Home is clicked', () => {
    const onGoHome = vi.fn();
    
    render(
      <ErrorBoundary onGoHome={onGoHome}>
        <ThrowError shouldThrow={true} />
      </ErrorBoundary>
    );

    fireEvent.click(screen.getByText('Go Home'));

    expect(onGoHome).toHaveBeenCalled();
  });

  it('renders custom fallback component when provided', () => {
  interface CustomFallbackProps { error: Error; resetError: () => void }
  const CustomFallback = ({ error, resetError }: CustomFallbackProps) => (
      <div>
        <h1>Custom Error</h1>
        <p>{error.message}</p>
        <button onClick={resetError}>Reset</button>
      </div>
    );

    render(
      <ErrorBoundary fallback={CustomFallback}>
        <ThrowError shouldThrow={true} />
      </ErrorBoundary>
    );

    expect(screen.getByText('Custom Error')).toBeInTheDocument();
    expect(screen.getByText('Test error')).toBeInTheDocument();
    expect(screen.getByText('Reset')).toBeInTheDocument();
  });
});

describe('withErrorBoundary', () => {
  it('wraps component with error boundary', () => {
    const TestComponent = () => <div>Test Component</div>;
    const WrappedComponent = withErrorBoundary(TestComponent);

    render(<WrappedComponent />);

    expect(screen.getByText('Test Component')).toBeInTheDocument();
  });

  it('catches errors in wrapped component', () => {
    const WrappedComponent = withErrorBoundary(ThrowError);

    render(<WrappedComponent shouldThrow={true} />);

    expect(screen.getByText('Something went wrong')).toBeInTheDocument();
  });

  it('passes error boundary props to wrapper', () => {
    const onError = vi.fn();
    const WrappedComponent = withErrorBoundary(ThrowError, { onError });

    render(<WrappedComponent shouldThrow={true} />);

    expect(onError).toHaveBeenCalled();
  });
});